wandb: Currently logged in as: rodion-ai. Use `wandb login --relogin` to force relogin
wandb: ERROR Error while calling W&B API: project not found (<Response [404]>)
Loaded configs...
Problem at: /gpfs/space/home/rodion/ttm/TrustAI-TTM-Energy/cluster/parsing/t5/t5_trainer.py 102 t5_trainer
wandb: ERROR It appears that you do not have permission to access the requested resource. Please reach out to the project owner to grant you access. If you have the correct permissions, verify that there are no issues with your networking setup.(Error 404: Not Found)
Traceback (most recent call last):
  File "/gpfs/space/home/rodion/ttm/TrustAI-TTM-Energy/cluster/parsing/t5/start_fine_tuning.py", line 105, in <module>
    main(args)
  File "/gpfs/space/home/rodion/ttm/TrustAI-TTM-Energy/cluster/parsing/t5/start_fine_tuning.py", line 91, in main
    t5_trainer(t5_params,
  File "/gpfs/space/home/rodion/ttm/TrustAI-TTM-Energy/cluster/parsing/t5/t5_trainer.py", line 102, in t5_trainer
    run = wandb.init(project="project-ttm", entity="dslack")
  File "/gpfs/space/home/rodion/ttm/venv_energy/lib/python3.9/site-packages/wandb/sdk/wandb_init.py", line 1195, in init
    raise e
  File "/gpfs/space/home/rodion/ttm/venv_energy/lib/python3.9/site-packages/wandb/sdk/wandb_init.py", line 1176, in init
    run = wi.init()
  File "/gpfs/space/home/rodion/ttm/venv_energy/lib/python3.9/site-packages/wandb/sdk/wandb_init.py", line 785, in init
    raise error
wandb.errors.CommError: It appears that you do not have permission to access the requested resource. Please reach out to the project owner to grant you access. If you have the correct permissions, verify that there are no issues with your networking setup.(Error 404: Not Found)
srun: error: falcon2: task 0: Exited with exit code 1
